/lhome/ific/f/fkellere/miniconda/envs/IC-3.8-2022-04-13/lib/python3.8/site-packages/torch/utils/data/dataloader.py:557: UserWarning: This DataLoader will create 3 worker processes in total. Our suggested max number of worker in current system is 1, which is smaller than what this DataLoader is going to create. Please be aware that excessive worker creation might get DataLoader running slow or even freeze, lower the worker number to avoid potential slowness/freeze if necessary.
  warnings.warn(_create_warning_msg(
0it [00:00, ?it/s]0it [00:11, ?it/s, Loss=0.00000, AvgLoss=0.00000, Acc=0.51953, AvgAcc=0.51953]1it [00:11, 11.31s/it, Loss=0.00000, AvgLoss=0.00000, Acc=0.51953, AvgAcc=0.51953]1it [00:11, 11.31s/it, Loss=0.00000, AvgLoss=0.00000, Acc=0.52539, AvgAcc=0.52246]2it [00:11,  4.82s/it, Loss=0.00000, AvgLoss=0.00000, Acc=0.52539, AvgAcc=0.52246]2it [00:11,  5.80s/it, Loss=0.00000, AvgLoss=0.00000, Acc=0.52539, AvgAcc=0.52246]
Traceback (most recent call last):
  File "train.py", line 705, in <module>
    main(args)
  File "train.py", line 661, in main
    test_metric, scores, labels, observers = evaluate(model, test_loader, dev, epoch=None, for_training=False, tb_helper=tb)
  File "/lhome/ific/f/fkellere/weaver-benchmark/weaver/utils/nn/tools.py", line 138, in evaluate_classification
    for X, y, Z in tq:
  File "/lhome/ific/f/fkellere/miniconda/envs/IC-3.8-2022-04-13/lib/python3.8/site-packages/tqdm/std.py", line 1178, in __iter__
    for obj in iterable:
  File "/lhome/ific/f/fkellere/miniconda/envs/IC-3.8-2022-04-13/lib/python3.8/site-packages/torch/utils/data/dataloader.py", line 652, in __next__
    data = self._next_data()
  File "/lhome/ific/f/fkellere/miniconda/envs/IC-3.8-2022-04-13/lib/python3.8/site-packages/torch/utils/data/dataloader.py", line 1327, in _next_data
    return self._process_data(data)
  File "/lhome/ific/f/fkellere/miniconda/envs/IC-3.8-2022-04-13/lib/python3.8/site-packages/torch/utils/data/dataloader.py", line 1373, in _process_data
    data.reraise()
  File "/lhome/ific/f/fkellere/miniconda/envs/IC-3.8-2022-04-13/lib/python3.8/site-packages/torch/_utils.py", line 461, in reraise
    raise exception
IndexError: Caught IndexError in DataLoader worker process 2.
Original Traceback (most recent call last):
  File "/lhome/ific/f/fkellere/miniconda/envs/IC-3.8-2022-04-13/lib/python3.8/site-packages/torch/utils/data/_utils/worker.py", line 246, in _worker_loop
    fetcher = _DatasetKind.create_fetcher(dataset_kind, dataset, auto_collation, collate_fn, drop_last)
  File "/lhome/ific/f/fkellere/miniconda/envs/IC-3.8-2022-04-13/lib/python3.8/site-packages/torch/utils/data/dataloader.py", line 76, in create_fetcher
    return _utils.fetch._IterableDatasetFetcher(dataset, auto_collation, collate_fn, drop_last)
  File "/lhome/ific/f/fkellere/miniconda/envs/IC-3.8-2022-04-13/lib/python3.8/site-packages/torch/utils/data/_utils/fetch.py", line 21, in __init__
    self.dataset_iter = iter(dataset)
  File "/lhome/ific/f/fkellere/weaver-benchmark/weaver/utils/dataset.py", line 362, in __iter__
    return _SimpleIter(**kwargs)
  File "/lhome/ific/f/fkellere/weaver-benchmark/weaver/utils/dataset.py", line 155, in __init__
    self.restart()
  File "/lhome/ific/f/fkellere/weaver-benchmark/weaver/utils/dataset.py", line 184, in restart
    '\n'.join(self.filelist[: 3]) + '\n ... ' + self.filelist[-1],)
IndexError: list index out of range

